# 47장. 에러 처리

---

**47.2 try..carch…finally 문**

 **try..carch…finally 문**

- 에러를 처리하는 방법으로 3개의 코드 블록으로 구성
- try문에서 에러가 발생하면 catch문의 err 변수에 전달되고 catch 구문이 실행된다.
- finally는 생략 가능하고 에러 발생과 상관없이 반드시 한 번 실행된다.
- try..carch…finally 문으로 에러를 처리하면 프로그램이 강제 종료되지 않는다

```jsx
try {
  // 에러가 일어날 수도 있는 작업들에 대한 코드
} catch(error) {
  // 에러가 일어난다면 분기해서 실행될 코드들
} finally {
  // 에러가 일어나든, 일어나지 않든 실행될 코드들
}
```

---

**47.3 Error 객체**

**Error 객체**

- Error 생성자 함수는 에러 객체를 생성한다.
- Error 생성자 함수에는 에러를 설명하는 에러 메시지를 인수로 전달할 수 있다.

```jsx
const error = new Error('invalid');
```

- 에러 객체는 `message`와 `stack` 프로퍼티를 갖는다.
- `message` 프로퍼티는 에러 메시지를, `stack` 프로퍼티는 에러를 발생시킨 콜 스택의 호출 정보를 나타내는 문자열이 담긴다.
- 자바스크립트는 Error 생성자 함수를 포함해 7가지의 에러 객체를 생성할 수 있는 Error 생성자 함수를 제공한다.

| 생성자 함수 | 만들어지는 Error 객체 |
| --- | --- |
| Error | 일반적인 에러 객체 |
| SyntaxError | 자바스크립트 문법에 맞지 않는 문을 해석할 떄 발생하는 에러 객체 |
| referenceError | 참조할 수 없는 식별자를 참조했을 때 발생하는 에러 객체 |
| TypeError | 피연산자 또는 인수의 데이터 타입이 유효하지 않을 때 발생하는 에러 객체 |
| RangeError | 숫자값의 허용 범위를 벗어났을 때 발생하는 에러 객체 |
| URIError | endodeURI 또는 decodeURI 함수에 부적절한 인수를 전달했을 때 발생하는 에러 객체 |
| EvalError | eval 함수에서 발생하는 에러 객체 |

```jsx
1 @ 1; // SyntaxError: Invalid or unexpected token
foo(); // ReferenceError: foo is not defined
null.foo; // TypeError: Cannot read property 'foo' of null
new Array(-1); // RangeError: Invalid array length
decodeURIComponent('%'); // URIError: URI malforme
```

---

**47.4 thorw 문**
- Error 객체만 생성한다고 에러가 발생하는 것이 아니다.
- try 코드 블록에서 throw 문으로 에러 객체를 던져야 한다.

```jsx
try{
  // 에러 객체를 던지면 catch 코드 블록이 실행되기 시작한다.
  throw new Error('something wrong');
} catch(error){
  console.log(error);
}
```
```jsx
// 외부에서 전달 받은 콜백 함수를 n번만큼 반복 호출한다.
const repeat = (n, f) => {
  // 매개변수 f에 전달된 인수가 함수가 아니면 TypeError를 발생시킨다.
  if(typeof f !== 'function') throw new TypeError('f must be a function');
  
  for(let i = 0; i < n; i++){
    f(i); // i를 전달하면서 f를 호출
  }
};

try {
  repeat(2,1); // 2번쨰 인수가 콜백함수가 아니므로 TypeError가 발생
} catch (err) {
  cosnole.error(err); // TypeError: f must be a function
}
```

---

**47.4 에러의 전파**
- 에러는 호출자 방향(실행 중인 실행 컨텍스트가 푸시되기 직전에 푸시된 실행 컨텍스트 방향)으로 전파된다.
```jsx
const foo = () => { throw Error('foo에서 발생한 에러'); }; // 4

const bar = () => {
  foo(); // 3 
};

const baz = () => {
  bar(); // 2
};

try {
  baz(); // 1
}catch (err) {
  console.error(err);
}
```

- 이때 foo 함수가 throw한 에러는 다음과 같이 호출자에게 전파되어 전역에서 캐치된다.
- 이처럼 throw된 에러를 캐치하지 않으면 호출자 방향으로 전파된다.
- throw된 에러를 어디에서도 캐치하지 않으면 프로그램은 강제 종료된다.
- setTimeout이나 프로미스 후속 처리 메서드의 콜백 함수는 호출자가 없다는 것이다.
- setTimeout이나 프로미스 후속 처리 메서드의 콜백 함수는 태스크 큐나 마이크로 태스크 큐에 일시 저장되었다가 콜 스택이 비면 이밴트 루프에 의해 콜 스택으로 푸시되어 실행된다.
- 이때 콜 스택에 푸시된 콜백 함수의 실행 컨텍스트는 콜 스택의 가장 하부에 존재하게 된다.
- 따라서 에러를 전파할 호출자가 존재하지 않는다.


---

**QUIZ**
```jsx
const foo = () => {
  setTimeout(() => {
    try {
      throw new TypeError("something wrong");
    } catch (error) {
      console.log(error);
    }
  }, 0);
}; // 4

const bar = () => {
  foo(); // 3
  try {
    throw new Error("something wrong");
  } catch (error) {
    console.log(error);
  }
};

const baz = () => {
  bar(); // 2
};

try {
  baz(); // 1
} catch (err) {
  console.error(err);
}
```
